<mujoco model="abb_arm">
    <compiler angle="radian" />
    <size njmax="500" nconmax="100" />
    <worldbody>
        <body name="base_dummy_link" pos="0 0 0">
            <inertial pos="0 0 0" mass="0" diaginertia="0 0 0" />
            <body name="base_link" pos="0 0 0">
                <inertial pos="0 0 0" quat="0.707107 0.707107 0 0" mass="1" diaginertia="1 1 0.5" />
                <geom size="0.0475 0.0385 0.015" pos="0 0 0.015" type="box" rgba="1 1 1 1" />
                <body name="shoulder_link" pos="0 0 0.015">
                    <inertial pos="0 0 0" quat="0.707107 0.707107 0 0" mass="1" diaginertia="1 1 0.5" />
                    <joint name="shoulder_joint" pos="0 0 0" axis="0 0 1" limited="true" range="-2.35619 2.35619" />
                    <geom size="0.06 0.06 0.03" pos="0 0 0.03" type="box" rgba="0.8 0 0 1" />
                    <body name="bigarm_link" pos="0 0 0.065">
                        <inertial pos="0 0 0" quat="0.707107 0.707107 0 0" mass="1" diaginertia="1 1 0.5" />
                        <joint name="bigarm_joint" pos="0 0 0" axis="0 1 0" limited="true" range="-1.48353 1.48353" />
                        <geom size="0.015 0.015 0.1" pos="0 0 0.0675" type="box" rgba="1 1 1 1" />
                        <body name="forearm_link" pos="0 0 0.145">
                            <inertial pos="0 0 0" quat="0.707107 0.707107 0 0" mass="1" diaginertia="1 1 0.5" />
                            <joint name="forearm_joint" pos="0 0 0" axis="0 1 0" limited="true" range="0.270796 2.8708" />
                            <geom size="0.02 0.09" pos="0 0 0.0935" type="cylinder" rgba="0 0 0 1" />
                            <body name="gripper_link" pos="0 0 0.18">
                                <inertial pos="0 0 0" quat="0.707107 0.707107 0 0" mass="1" diaginertia="1 1 0.5" />
                                <joint name="gripper_joint" pos="0 0 0" axis="0 1 0" limited="true" range="-2.36 2.36" />
                                <geom size="0.01 0.015 0.015" pos="0 0 0.0115" type="box" rgba="0.8 0 0 1" />
                                <body name="chuck_link" pos="0 0 0.1">
                                    <inertial pos="0 0 0" quat="0.707107 0.707107 0 0" mass="1" diaginertia="1 1 0.5" />
                                    <joint name="chuck_joint" pos="0 0 0" axis="0 0 1" limited="true" range="-2.36 2.36" />
                                    <geom size="0.02 0.0125" pos="0 0 -0.07" type="cylinder" rgba="0.5 0.5 0 1" />
                                    <body name="left_finger_link" pos="0 0 -0.057">
                                        <inertial pos="0 0 0" quat="0.707107 0.707107 0 0" mass="1" diaginertia="1 1 0.5" />
                                        <joint name="hand_joint" pos="0 0 0" axis="1 0 0" limited="true" range="-2.36 2.36" />
                                        <geom size="0.0025 0.01 0.0475" pos="0 0 0.047" type="box" rgba="1 1 1 1" />
                                    </body>
                                </body>
                            </body>
                        </body>
                    </body>
                </body>
            </body>
        </body>
    </worldbody>
</mujoco>
