<mujoco model="abb_arm">
    <compiler angle="radian" />
    <size njmax="500" nconmax="100" />
    <worldbody>
        <body name="base_dummy_link" pos="0 0 0">
            <inertial pos="0 0 0" mass="0" diaginertia="0 0 0" />
            <body name="base_link" pos="-0.25 0 0">
                <inertial pos="0 0 0" quat="0.707107 0.707107 0 0" mass="0.5" diaginertia="1 1 0.5" />
                <geom size="0.0475 0.0385 0.01" pos="0 0 0.015" type="box" />
                <body name="shoulder_link" pos="0 0 0.03">
                    <inertial pos="0 0 0" quat="0.707107 0.707107 0 0" mass="0.1" diaginertia="1 1 0.5" />
                    <joint name="shoulder_joint" pos="0 0 0" axis="0 0 1" limited="true" range="-2.094 2.094" />
                    <geom size="0.06 0.03 0.025" pos="0 0 0.025" type="box" />
                    <body name="bigarm_link" pos="0.04 0 0.05">
                        <inertial pos="0 0 0" quat="0.707107 0.707107 0 0" mass="0.1" diaginertia="1 1 0.5" />
                        <joint name="bigarm_joint" pos="0 0 0" axis="0 1 0" limited="true" range="-1.48353 1.48353" />
                        <geom size="0.02 0.02 0.065" pos="0 0 0.065" type="box" />
                        <body name="elbow_link" pos="0 0 0.13">
                            <inertial pos="0 0 0" quat="0.707107 0.707107 0 0" mass="0.1" diaginertia="1 1 0.5" />
                            <joint name="elbow_joint" pos="0 0 0" axis="0 1 0" limited="true" range="0.785 2.356" />
                            <geom size="0.02 0.01" pos="0 0 0.01" type="cylinder" />
                            <body name="forearm_link" pos="0 0 0.02">
                                <inertial pos="0 0 0" quat="0.707107 0.707107 0 0" mass="0.1" diaginertia="1 1 0.5" />
                                <joint name="forearm_joint" pos="0 0 0" axis="0 0 1" limited="true" range="-2.094 2.094" />
                                <geom size="0.0125 0.0125 0.08" pos="0 0 0.08" type="box" />
                                <body name="hand_link" pos="0 0 0.16">
                                    <inertial pos="0 0 0" quat="0.707107 0.707107 0 0" mass="0.1" diaginertia="1 1 0.5" />
                                    <joint name="hand_joint" pos="0 0 0" axis="0 1 0" limited="true" range="-2.094 2.094" />
                                    <geom size="0.01 0.005 0.015" pos="0 0 0.015" type="box" />
                                    <body name="endeffector" pos="0 0 0.03">
                                        <inertial pos="0 0 0" quat="0.707107 0.707107 0 0" mass="0.1" diaginertia="1 1 0.5" />
                                        <joint name="endeff_joint" pos="0 0 0" axis="0 0 1" limited="true" range="-2.094 2.094" />
                                        <geom size="0.04 0.0025 0.0025" pos="-0.04 0 0.0025" type="box" />
                                    </body>
                                </body>
                            </body>
                        </body>
                    </body>
                </body>
            </body>
        </body>
    </worldbody>
</mujoco>
