<mujoco model="dobot_arm">
    <compiler angle="radian" />
    <size njmax="500" nconmax="100" />
    <worldbody>
        <body name="base_dummy_link" pos="0 0 0">
            <inertial pos="0 0 0" mass="0" diaginertia="0 0 0" />
            <body name="base_link" pos="0 0 0">
                <inertial pos="0 0 0" quat="0.707107 0.707107 0 0" mass="1" diaginertia="1 1 0.5" />
                <geom size="0.084 0.084 0.0275" pos="0 0 0.0275" type="box" rgba="1 1 1 1" />
                <body name="shoulder_link" pos="0 0 0.0425">
                    <inertial pos="0 0 0" quat="0.707107 0.707107 0 0" mass="1" diaginertia="1 1 0.5" />
                    <joint name="shoulder_joint" pos="0 0 0" axis="0 0 1" limited="true" range="-2.35619 2.35619" />
                    <geom size="0.06 0.0325" pos="0 0 0.0425" type="cylinder" rgba="0.8 0 0 1" />
                    <body name="bigarm_link" pos="0 0 0.109">
                        <inertial pos="0 0 0" quat="0.707107 0.707107 0 0" mass="1" diaginertia="1 1 0.5" />
                        <joint name="bigarm_joint" pos="0 0 0" axis="0 1 0" limited="true" range="0 1.48353" />
                        <geom size="0.03 0.1" pos="0 0 0.0675" type="cylinder" rgba="1 1 1 1" />
                        <body name="forearm_link" pos="0.015 0 0.14">
                            <inertial pos="0 0 0" quat="0.707107 0.707107 0 0" mass="1" diaginertia="1 1 0.5" />
                            <joint name="forearm_joint" pos="0 0 0" axis="0 1 0" limited="true" range="0.270796 2.8708" />
                            <geom size="0.03 0.105" pos="-0.035 0 0.0935" type="cylinder" rgba="0 0 0 1" />
                            <body name="fake_link" pos="0 0 0.21">
                                <inertial pos="0 0 0" quat="0.707107 0.707107 0 0" mass="1" diaginertia="1 1 0.5" />
                                <joint name="fake_joint" pos="0 0 0" axis="0 1 0" limited="true" range="-2.8708 0.270796" />
                                <geom size="0.04 0.015 0.015" pos="0.02 0 0.0115" type="box" rgba="0.8 0 0 1" />
                                <body name="chuck_link" pos="0.05 0 0.0405">
                                    <inertial pos="0 0 0" quat="0.707107 0.707107 0 0" mass="1" diaginertia="1 1 0.5" />
                                    <joint name="chuck_joint" pos="0 0 0" axis="0 0 1" limited="true" range="-2.36 2.36" />
                                    <geom size="0.01 0.035" pos="0.005 0 -0.075" type="cylinder" rgba="0.5 0.5 0 1" />
                                    <body name="stick_link" pos="0 0 -0.11" quat="0.968912 0 0.247404 0">
                                        <inertial pos="0 0 0" quat="0.707107 0.707107 0 0" mass="1" diaginertia="1 1 0.5" />
                                        <geom size="0.0055 0.035" quat="0.877583 0 0.479426 0" type="cylinder" rgba="1 1 1 1" />
                                    </body>
                                </body>
                            </body>
                        </body>
                    </body>
                </body>
            </body>
        </body>
    </worldbody>
    <actuator>
		<velocity name="shoulder_motor" joint="shoulder_joint"/>
		<velocity name="bigarm_motor" joint="bigarm_joint"/>
        <velocity name="forearm_motor" joint="forearm_joint"/>
        <velocity name="fake_joint" joint="chuck_joint"/>
        <velocity name="chuck_motor" joint="chuck_joint"/>
	</actuator>
</mujoco>
